Workbook

Sheet Tabellenblatt1
A1: Nr. | B1: Signatur | C1: [Nummer Signatur] | D1: [Nummer Laßberg] | E1: HSP-ID KOD | F1: Permalink KOD | G1: HSP-ID-Beschreibung | H1: Permalink Beschreibung
A2: =ROW()-1 -> 1 | B2: =CONCATENATE("Cod. Donaueschingen ",C2) -> Cod. Donaueschingen 63 | C2: 63 | D2: 174 | E2: =IF(COUNTIF('HSP-Abzug'!$A$2:$A$300,B2)=1,VLOOKUP(B2,'HSP-Abzug'!$A$3:$L$301,7,FALSE),"") -> HSP-ea91c7ad-4d93-3fb4-8faf-1301b1dba70c | F2: =IF(COUNTIF('HSP-Abzug'!$A$2:$A$300,B2)=1,VLOOKUP(B2,'HSP-Abzug'!$A$3:$L$301,11,FALSE),"") -> https://resolver.staatsbibliothek-berlin.de/HSP000539EF00000000 | G2: =IF(COUNTIF('HSP-Abzug'!$A$2:$A$300,B3)=1,VLOOKUP(B3,'HSP-Abzug'!$A$3:$L$301,7,FALSE),"") -> HSP-31655ad3-cde6-3c7d-b0a6-dff36cb6843e | H2: =IF(COUNTIF('HSP-Abzug'!$A$2:$A$300,B3)=1,VLOOKUP(B3,'HSP-Abzug'!$A$3:$L$301,11,FALSE),"") -> https://resolver.staatsbibliothek-berlin.de/HSP000539F000000000
A3: =ROW()-1 -> 2 | B3: =CONCATENATE("Cod. Donaueschingen ",C3) -> Cod. Donaueschingen 64 | C3: 64 | D3: - | E3: =IF(COUNTIF('HSP-Abzug'!$A$2:$A$300,B3)=1,VLOOKUP(B3,'HSP-Abzug'!$A$3:$L$301,7,FALSE),"") -> HSP-31655ad3-cde6-3c7d-b0a6-dff36cb6843e | F3: =IF(COUNTIF('HSP-Abzug'!$A$2:$A$300,B3)=1,VLOOKUP(B3,'HSP-Abzug'!$A$3:$L$301,11,FALSE),"") -> https://resolver.staatsbibliothek-berlin.de/HSP000539F000000000 | G3: =IF(COUNTIF('HSP-Abzug'!$A$2:$A$300,B4)=1,VLOOKUP(B4,'HSP-Abzug'!$A$3:$L$301,7,FALSE),"") -> HSP-1244bf27-76de-3d0b-a81e-d57aec934668 | H3: =IF(COUNTIF('HSP-Abzug'!$A$2:$A$300,B4)=1,VLOOKUP(B4,'HSP-Abzug'!$A$3:$L$301,11,FALSE),"") -> https://resolver.staatsbibliothek-berlin.de/HSP000539F100000000
A4: =ROW()-1 -> 3 | B4: =CONCATENATE("Cod. Donaueschingen ",C4) -> Cod. Donaueschingen 66 | C4: 66 | D4: 223 | E4: =IF(COUNTIF('HSP-Abzug'!$A$2:$A$300,B4)=1,VLOOKUP(B4,'HSP-Abzug'!$A$3:$L$301,7,FALSE),"") -> HSP-1244bf27-76de-3d0b-a81e-d57aec934668 | F4: =IF(COUNTIF('HSP-Abzug'!$A$2:$A$300,B4)=1,VLOOKUP(B4,'HSP-Abzug'!$A$3:$L$301,11,FALSE),"") -> https://resolver.staatsbibliothek-berlin.de/HSP000539F100000000 | G4: =IF(COUNTIF('HSP-Abzug'!$A$2:$A$300,B5)=1,VLOOKUP(B5,'HSP-Abzug'!$A$3:$L$301,7,FALSE),"") -> HSP-423feb6b-cf26-3213-974a-9a4af84f18a2 | H4: =IF(COUNTIF('HSP-Abzug'!$A$2:$A$300,B5)=1,VLOOKUP(B5,'HSP-Abzug'!$A$3:$L$301,11,FALSE),"") -> https://resolver.staatsbibliothek-berlin.de/HSP000539F200000000
A5: =ROW()-1 -> 4 | B5: =CONCATENATE("Cod. Donaueschingen ",C5) -> Cod. Donaueschingen 67 | C5: 67 | D5: 203 | E5: =IF(COUNTIF('HSP-Abzug'!$A$2:$A$300,B5)=1,VLOOKUP(B5,'HSP-Abzug'!$A$3:$L$301,7,FALSE),"") -> HSP-423feb6b-cf26-3213-974a-9a4af84f18a2 | F5: =IF(COUNTIF('HSP-Abzug'!$A$2:$A$300,B5)=1,VLOOKUP(B5,'HSP-Abzug'!$A$3:$L$301,11,FALSE),"") -> https://resolver.staatsbibliothek-berlin.de/HSP000539F200000000 | G5: =IF(COUNTIF('HSP-Abzug'!$A$2:$A$300,B5)=1,VLOOKUP(B5,'HSP-Abzug'!$A$3:$L$301,10,FALSE),"") -> HSP-3377720a-4adf-3eb5-b89b-ea56882ad801 | H5: =IF(COUNTIF('HSP-Abzug 2'!$A$2:$A$300,B5)=1,VLOOKUP(B5,'HSP-Abzug 2'!$A$3:$P$301,9,FALSE),"") -> https://resolver.staatsbibliothek-berlin.de/HSP00062F6D00000000
A6: =ROW()-1 -> 5 | B6: =CONCATENATE("Cod. Donaueschingen ",C6) -> Cod. Donaueschingen 68 | C6: 68 | D6: 215 | E6: =IF(COUNTIF('HSP-Abzug'!$A$2:$A$300,B6)=1,VLOOKUP(B6,'HSP-Abzug'!$A$3:$L$301,7,FALSE),"") -> HSP-4c50f7dd-8057-3084-b9c7-5b4f0d7bd581 | F6: =IF(COUNTIF('HSP-Abzug'!$A$2:$A$300,B6)=1,VLOOKUP(B6,'HSP-Abzug'!$A$3:$L$301,11,FALSE),"") -> https://resolver.staatsbibliothek-berlin.de/HSP000539F300000000 | G6: =IF(COUNTIF('HSP-Abzug'!$A$2:$A$300,B6)=1,VLOOKUP(B6,'HSP-Abzug'!$A$3:$L$301,10,FALSE),"") -> HSP-1f6f6dfc-9ceb-3701-afec-b08af54b7ba6 | H6: =IF(COUNTIF('HSP-Abzug 2'!$A$2:$A$300,B6)=1,VLOOKUP(B6,'HSP-Abzug 2'!$A$3:$P$301,9,FALSE),"") -> https://resolver.staatsbibliothek-berlin.de/HSP00062F6E00000000
A7: =ROW()-1 -> 6 | B7: =CONCATENATE("Cod. Donaueschingen ",C7) -> Cod. Donaueschingen 70 | C7: 70 | D7: 186 | E7: =IF(COUNTIF('HSP-Abzug'!$A$2:$A$300,B7)=1,VLOOKUP(B7,'HSP-Abzug'!$A$3:$L$301,7,FALSE),"") -> HSP-66a860e9-f506-3899-b7ba-74f8a4d35727 | F7: =IF(COUNTIF('HSP-Abzug'!$A$2:$A$300,B7)=1,VLOOKUP(B7,'HSP-Abzug'!$A$3:$L$301,11,FALSE),"") -> https://resolver.staatsbibliothek-berlin.de/HSP000539F500000000 | G7: =IF(COUNTIF('HSP-Abzug'!$A$2:$A$300,B7)=1,VLOOKUP(B7,'HSP-Abzug'!$A$3:$L$301,10,FALSE),"") -> HSP-234d82af-9c75-3e26-8341-55fd9353a0da | H7: =IF(COUNTIF('HSP-Abzug 2'!$A$2:$A$300,B7)=1,VLOOKUP(B7,'HSP-Abzug 2'!$A$3:$P$301,9,FALSE),"") -> https://resolver.staatsbibliothek-berlin.de/HSP00062F6C00000000
A8: =ROW()-1 -> 7 | B8: =CONCATENATE("Cod. Donaueschingen ",C8) -> Cod. Donaueschingen 72 | C8: 72 | D8: 204 | E8: =IF(COUNTIF('HSP-Abzug'!$A$2:$A$300,B8)=1,VLOOKUP(B8,'HSP-Abzug'!$A$3:$L$301,7,FALSE),"") -> HSP-e8db0dc3-52f6-33c6-93e7-7d0b61b0c1a6 | F8: =IF(COUNTIF('HSP-Abzug'!$A$2:$A$300,B8)=1,VLOOKUP(B8,'HSP-Abzug'!$A$3:$L$301,11,FALSE),"") -> https://resolver.staatsbibliothek-berlin.de/HSP000539F700000000 | G8: =IF(COUNTIF('HSP-Abzug'!$A$2:$A$300,B8)=1,VLOOKUP(B8,'HSP-Abzug'!$A$3:$L$301,10,FALSE),"") -> HSP-2d1c8fb8-08bc-3a84-bf47-1c4846908512 | H8: =IF(COUNTIF('HSP-Abzug 2'!$A$2:$A$300,B8)=1,VLOOKUP(B8,'HSP-Abzug 2'!$A$3:$P$301,9,FALSE),"") -> https://resolver.staatsbibliothek-berlin.de/HSP00062F6F00000000
A9: =ROW()-1 -> 8 | B9: =CONCATENATE("Cod. Donaueschingen ",C9) -> Cod. Donaueschingen 73 | C9: 73 | D9: 176 | E9: =IF(COUNTIF('HSP-Abzug'!$A$2:$A$300,B9)=1,VLOOKUP(B9,'HSP-Abzug'!$A$3:$L$301,7,FALSE),"") -> HSP-76153bee-8501-3630-93c1-aa943f85ba68 | F9: =IF(COUNTIF('HSP-Abzug'!$A$2:$A$300,B9)=1,VLOOKUP(B9,'HSP-Abzug'!$A$3:$L$301,11,FALSE),"") -> https://resolver.staatsbibliothek-berlin.de/HSP000539F800000000 | G9: =IF(COUNTIF('HSP-Abzug'!$A$2:$A$300,B9)=1,VLOOKUP(B9,'HSP-Abzug'!$A$3:$L$301,10,FALSE),"") -> HSP-986fc6fc-f5ec-31c3-92f5-fec7ddca08ac | H9: =IF(COUNTIF('HSP-Abzug 2'!$A$2:$A$300,B9)=1,VLOOKUP(B9,'HSP-Abzug 2'!$A$3:$P$301,9,FALSE),"") -> https://resolver.staatsbibliothek-berlin.de/HSP00062F6200000000
A10: =ROW()-1 -> 9 | B10: =CONCATENATE("Cod. Donaueschingen ",C10) -> Cod. Donaueschingen 74 | C10: 74 | D10: 175 | E10: =IF(COUNTIF('HSP-Abzug'!$A$2:$A$300,B10)=1,VLOOKUP(B10,'HSP-Abzug'!$A$3:$L$301,7,FALSE),"") -> HSP-58bc2371-1364-31bf-b940-2959267f60ab | F10: =IF(COUNTIF('HSP-Abzug'!$A$2:$A$300,B10)=1,VLOOKUP(B10,'HSP-Abzug'!$A$3:$L$301,11,FALSE),"") -> https://resolver.staatsbibliothek-berlin.de/HSP000539F900000000 | G10: =IF(COUNTIF('HSP-Abzug'!$A$2:$A$300,B10)=1,VLOOKUP(B10,'HSP-Abzug'!$A$3:$L$301,10,FALSE),"") -> HSP-cc78152f-8987-354e-9903-1e65dc9e41e2 | H10: =IF(COUNTIF('HSP-Abzug 2'!$A$2:$A$300,B10)=1,VLOOKUP(B10,'HSP-Abzug 2'!$A$3:$P$301,9,FALSE),"") -> https://resolver.staatsbibliothek-berlin.de/HSP00062F8F00000000
A11: =ROW()-1 -> 10 | B11: =CONCATENATE("Cod. Donaueschingen ",C11) -> Cod. Donaueschingen 75a | C11: 75a | D11: 221 | E11: =IF(COUNTIF('HSP-Abzug'!$A$2:$A$300,B11)=1,VLOOKUP(B11,'HSP-Abzug'!$A$3:$L$301,7,FALSE),"") -> HSP-01aad6fa-006e-363e-a1d0-1e45cf1981cb | F11: =IF(COUNTIF('HSP-Abzug'!$A$2:$A$300,B11)=1,VLOOKUP(B11,'HSP-Abzug'!$A$3:$L$301,11,FALSE),"") -> https://resolver.staatsbibliothek-berlin.de/HSP000539FA00000000 | G11: =IF(COUNTIF('HSP-Abzug'!$A$2:$A$300,B11)=1,VLOOKUP(B11,'HSP-Abzug'!$A$3:$L$301,10,FALSE),"") -> HSP-f4e6bbdb-89b6-32f6-98a5-34c29343f548 | H11: =IF(COUNTIF('HSP-Abzug 2'!$A$2:$A$300,B11)=1,VLOOKUP(B11,'HSP-Abzug 2'!$A$3:$P$301,9,FALSE),"") -> https://resolver.staatsbibliothek-berlin.de/HSP00062F7100000000
A12: =ROW()-1 -> 11 | B12: =CONCATENATE("Cod. Donaueschingen ",C12) -> Cod. Donaueschingen 75b | C12: 75b | D12: - | E12: =IF(COUNTIF('HSP-Abzug'!$A$2:$A$300,B12)=1,VLOOKUP(B12,'HSP-Abzug'!$A$3:$L$301,7,FALSE),"") -> HSP-d6b6f250-4558-3188-b685-f16e8557de8e | F12: =IF(COUNTIF('HSP-Abzug'!$A$2:$A$300,B12)=1,VLOOKUP(B12,'HSP-Abzug'!$A$3:$L$301,11,FALSE),"") -> https://resolver.staatsbibliothek-berlin.de/HSP000539FB00000000 | G12: =IF(COUNTIF('HSP-Abzug'!$A$2:$A$300,B12)=1,VLOOKUP(B12,'HSP-Abzug'!$A$3:$L$301,10,FALSE),"") -> HSP-f7197a77-3ccf-34d0-84cb-8bddaf7fb4d7 | H12: =IF(COUNTIF('HSP-Abzug 2'!$A$2:$A$300,B12)=1,VLOOKUP(B12,'HSP-Abzug 2'!$A$3:$P$301,9,FALSE),"") -> https://resolver.staatsbibliothek-berlin.de/HSP00062F7200000000
A13: =ROW()-1 -> 12 | B13: =CONCATENATE("Cod. Donaueschingen ",C13) -> Cod. Donaueschingen 76 | C13: 76 | D13: - | E13: =IF(COUNTIF('HSP-Abzug'!$A$2:$A$300,B13)=1,VLOOKUP(B13,'HSP-Abzug'!$A$3:$L$301,7,FALSE),"") -> HSP-d1cea0b6-1d48-38ef-b142-f476fe3dfe75 | F13: =IF(COUNTIF('HSP-Abzug'!$A$2:$A$300,B13)=1,VLOOKUP(B13,'HSP-Abzug'!$A$3:$L$301,11,FALSE),"") -> https://resolver.staatsbibliothek-berlin.de/HSP000539FC00000000 | G13: =IF(COUNTIF('HSP-Abzug'!$A$2:$A$300,B13)=1,VLOOKUP(B13,'HSP-Abzug'!$A$3:$L$301,10,FALSE),"") -> HSP-7a45f8ab-42a9-3a3a-8c23-921b31725ac7 | H13: =IF(COUNTIF('HSP-Abzug 2'!$A$2:$A$300,B13)=1,VLOOKUP(B13,'HSP-Abzug 2'!$A$3:$P$301,9,FALSE),"") -> https://resolver.staatsbibliothek-berlin.de/HSP00062F7000000000
A14: =ROW()-1 -> 13 | B14: =CONCATENATE("Cod. Donaueschingen ",C14) -> Cod. Donaueschingen 77 | C14: 77 | D14: 179 | E14: =IF(COUNTIF('HSP-Abzug'!$A$2:$A$300,B14)=1,VLOOKUP(B14,'HSP-Abzug'!$A$3:$L$301,7,FALSE),"") -> HSP-5c995ce7-c173-37ac-a5b4-2f05414e1fbd | F14: =IF(COUNTIF('HSP-Abzug'!$A$2:$A$300,B14)=1,VLOOKUP(B14,'HSP-Abzug'!$A$3:$L$301,11,FALSE),"") -> https://resolver.staatsbibliothek-berlin.de/HSP000539FE00000000 | G14: =IF(COUNTIF('HSP-Abzug'!$A$2:$A$300,B14)=1,VLOOKUP(B14,'HSP-Abzug'!$A$3:$L$301,10,FALSE),"") -> HSP-d77acc6a-9c7d-30d3-ab68-f0722882a7f6 | H14: =IF(COUNTIF('HSP-Abzug 2'!$A$2:$A$300,B14)=1,VLOOKUP(B14,'HSP-Abzug 2'!$A$3:$P$301,9,FALSE),"") -> https://resolver.staatsbibliothek-berlin.de/HSP00062F9C00000000
A15: =ROW()-1 -> 14 | B15: =CONCATENATE("Cod. Donaueschingen ",C15) -> Cod. Donaueschingen 82 | C15: 82 | D15: 67, 178 | E15: =IF(COUNTIF('HSP-Abzug'!$A$2:$A$300,B15)=1,VLOOKUP(B15,'HSP-Abzug'!$A$3:$L$301,7,FALSE),"") -> HSP-7ecb5382-7f93-39c9-b79c-81638bfa2791 | F15: =IF(COUNTIF('HSP-Abzug'!$A$2:$A$300,B15)=1,VLOOKUP(B15,'HSP-Abzug'!$A$3:$L$301,11,FALSE),"") -> https://resolver.staatsbibliothek-berlin.de/HSP00053A0400000000 | G15: =IF(COUNTIF('HSP-Abzug'!$A$2:$A$300,B15)=1,VLOOKUP(B15,'HSP-Abzug'!$A$3:$L$301,10,FALSE),"") -> HSP-3cd2b544-4afc-3731-ab21-049c0af76415 | H15: =IF(COUNTIF('HSP-Abzug 2'!$A$2:$A$300,B15)=1,VLOOKUP(B15,'HSP-Abzug 2'!$A$3:$P$301,9,FALSE),"") -> https://resolver.staatsbibliothek-berlin.de/HSP00062F9F00000000
A16: =ROW()-1 -> 15 | B16: =CONCATENATE("Cod. Donaueschingen ",C16) -> Cod. Donaueschingen 83 | C16: 83 | D16: 211 | E16: =IF(COUNTIF('HSP-Abzug'!$A$2:$A$300,B16)=1,VLOOKUP(B16,'HSP-Abzug'!$A$3:$L$301,7,FALSE),"") -> HSP-4f4b23e7-5199-3d31-9505-d81bfa27f08d | F16: =IF(COUNTIF('HSP-Abzug'!$A$2:$A$300,B16)=1,VLOOKUP(B16,'HSP-Abzug'!$A$3:$L$301,11,FALSE),"") -> https://resolver.staatsbibliothek-berlin.de/HSP00053A0500000000 | G16: =IF(COUNTIF('HSP-Abzug'!$A$2:$A$300,B16)=1,VLOOKUP(B16,'HSP-Abzug'!$A$3:$L$301,10,FALSE),"") -> HSP-3012bdfa-0312-398d-b3d0-0f1c536fee5d | H16: =IF(COUNTIF('HSP-Abzug 2'!$A$2:$A$300,B16)=1,VLOOKUP(B16,'HSP-Abzug 2'!$A$3:$P$301,9,FALSE),"") -> https://resolver.staatsbibliothek-berlin.de/HSP00062F7500000000
A17: =ROW()-1 -> 16 | B17: =CONCATENATE("Cod. Donaueschingen ",C17) -> Cod. Donaueschingen 84 | C17: 84 | D17: 212 | E17: =IF(COUNTIF('HSP-Abzug'!$A$2:$A$300,B17)=1,VLOOKUP(B17,'HSP-Abzug'!$A$3:$L$301,7,FALSE),"") -> HSP-b7ae5441-aba8-3301-9b51-abc890acf22a | F17: =IF(COUNTIF('HSP-Abzug'!$A$2:$A$300,B17)=1,VLOOKUP(B17,'HSP-Abzug'!$A$3:$L$301,11,FALSE),"") -> https://resolver.staatsbibliothek-berlin.de/HSP00053A0600000000 | G17: =IF(COUNTIF('HSP-Abzug'!$A$2:$A$300,B17)=1,VLOOKUP(B17,'HSP-Abzug'!$A$3:$L$301,10,FALSE),"") -> HSP-814affe4-9167-36e6-af0d-d2a7ef0877cb | H17: =IF(COUNTIF('HSP-Abzug 2'!$A$2:$A$300,B17)=1,VLOOKUP(B17,'HSP-Abzug 2'!$A$3:$P$301,9,FALSE),"") -> https://resolver.staatsbibliothek-berlin.de/HSP00062F7700000000
A18: =ROW()-1 -> 17 | B18: =CONCATENATE("Cod. Donaueschingen ",C18) -> Cod. Donaueschingen 88 | C18: 88 | D18: 218 | E18: =IF(COUNTIF('HSP-Abzug'!$A$2:$A$300,B18)=1,VLOOKUP(B18,'HSP-Abzug'!$A$3:$L$301,7,FALSE),"") -> HSP-2176ef14-2e51-3ac4-b9c2-c9e4b1bb363c | F18: =IF(COUNTIF('HSP-Abzug'!$A$2:$A$300,B18)=1,VLOOKUP(B18,'HSP-Abzug'!$A$3:$L$301,11,FALSE),"") -> https://resolver.staatsbibliothek-berlin.de/HSP00053A0A00000000 | G18: =IF(COUNTIF('HSP-Abzug'!$A$2:$A$300,B18)=1,VLOOKUP(B18,'HSP-Abzug'!$A$3:$L$301,10,FALSE),"") -> HSP-84b2ca17-b9f0-3d26-b39a-10ad6caec7ca | H18: =IF(COUNTIF('HSP-Abzug 2'!$A$2:$A$300,B18)=1,VLOOKUP(B18,'HSP-Abzug 2'!$A$3:$P$301,9,FALSE),"") -> https://resolver.staatsbibliothek-berlin.de/HSP00062F7600000000
A19: =ROW()-1 -> 18 | B19: =CONCATENATE("Cod. Donaueschingen ",C19) -> Cod. Donaueschingen 89 | C19: 89 | D19: - | E19: =IF(COUNTIF('HSP-Abzug'!$A$2:$A$300,B19)=1,VLOOKUP(B19,'HSP-Abzug'!$A$3:$L$301,7,FALSE),"") -> HSP-59eeb9ec-c6ed-308d-9e50-c1d4d1fe0c83 | F19: =IF(COUNTIF('HSP-Abzug'!$A$2:$A$300,B19)=1,VLOOKUP(B19,'HSP-Abzug'!$A$3:$L$301,11,FALSE),"") -> https://resolver.staatsbibliothek-berlin.de/HSP00053A0B00000000 | G19: =IF(COUNTIF('HSP-Abzug'!$A$2:$A$300,B19)=1,VLOOKUP(B19,'HSP-Abzug'!$A$3:$L$301,10,FALSE),"") -> HSP-73f35cce-6dbb-3eb2-a79b-48fee3bcf222 | H19: =IF(COUNTIF('HSP-Abzug 2'!$A$2:$A$300,B19)=1,VLOOKUP(B19,'HSP-Abzug 2'!$A$3:$P$301,9,FALSE),"") -> https://resolver.staatsbibliothek-berlin.de/HSP00062F7A00000000
A20: =ROW()-1 -> 19 | B20: =CONCATENATE("Cod. Donaueschingen ",C20) -> Cod. Donaueschingen 92 | C20: 92 | D20: 190 | E20: =IF(COUNTIF('HSP-Abzug'!$A$2:$A$300,B20)=1,VLOOKUP(B20,'HSP-Abzug'!$A$3:$L$301,7,FALSE),"") -> HSP-8df42ad4-2ba9-3daf-a420-8625cd037ac7 | F20: =IF(COUNTIF('HSP-Abzug'!$A$2:$A$300,B20)=1,VLOOKUP(B20,'HSP-Abzug'!$A$3:$L$301,11,FALSE),"") -> https://resolver.staatsbibliothek-berlin.de/HSP00053A0E00000000 | G20: =IF(COUNTIF('HSP-Abzug'!$A$2:$A$300,B20)=1,VLOOKUP(B20,'HSP-Abzug'!$A$3:$L$301,10,FALSE),"") -> HSP-854947fb-e7de-32d1-8431-ae6afc0591bd | H20: =IF(COUNTIF('HSP-Abzug 2'!$A$2:$A$300,B20)=1,VLOOKUP(B20,'HSP-Abzug 2'!$A$3:$P$301,9,FALSE),"") -> https://resolver.staatsbibliothek-berlin.de/HSP00062FAC00000000
A21: =ROW()-1 -> 20 | B21: =CONCATENATE("Cod. Donaueschingen ",C21) -> Cod. Donaueschingen 95 | C21: 95 | D21: 214 | E21: =IF(COUNTIF('HSP-Abzug'!$A$2:$A$300,B21)=1,VLOOKUP(B21,'HSP-Abzug'!$A$3:$L$301,7,FALSE),"") -> HSP-9bff85dc-55e4-31cb-8cde-2ae62e8d3ebc | F21: =IF(COUNTIF('HSP-Abzug'!$A$2:$A$300,B21)=1,VLOOKUP(B21,'HSP-Abzug'!$A$3:$L$301,11,FALSE),"") -> https://resolver.staatsbibliothek-berlin.de/HSP00053A1100000000 | G21: =IF(COUNTIF('HSP-Abzug'!$A$2:$A$300,B21)=1,VLOOKUP(B21,'HSP-Abzug'!$A$3:$L$301,10,FALSE),"") -> HSP-5679c19f-1d18-3205-bf65-d88474dc14b3 | H21: =IF(COUNTIF('HSP-Abzug 2'!$A$2:$A$300,B21)=1,VLOOKUP(B21,'HSP-Abzug 2'!$A$3:$P$301,9,FALSE),"") -> https://resolver.staatsbibliothek-berlin.de/HSP00062FB000000000
A22: =ROW()-1 -> 21 | B22: =CONCATENATE("Cod. Donaueschingen ",C22) -> Cod. Donaueschingen 104 | C22: 104 | D22: 177 | E22: =IF(COUNTIF('HSP-Abzug'!$A$2:$A$300,B22)=1,VLOOKUP(B22,'HSP-Abzug'!$A$3:$L$301,7,FALSE),"") -> HSP-96a15530-bf95-375e-a6a9-e34efb79e8fb | F22: =IF(COUNTIF('HSP-Abzug'!$A$2:$A$300,B22)=1,VLOOKUP(B22,'HSP-Abzug'!$A$3:$L$301,11,FALSE),"") -> https://resolver.staatsbibliothek-berlin.de/HSP0005398400000000 | G22: =IF(COUNTIF('HSP-Abzug'!$A$2:$A$300,B22)=1,VLOOKUP(B22,'HSP-Abzug'!$A$3:$L$301,10,FALSE),"") -> HSP-11d6b533-63f3-36bd-91aa-4a8d5ef766fd | H22: =IF(COUNTIF('HSP-Abzug 2'!$A$2:$A$300,B22)=1,VLOOKUP(B22,'HSP-Abzug 2'!$A$3:$P$301,9,FALSE),"") -> https://resolver.staatsbibliothek-berlin.de/HSP00062F5100000000
A23: =ROW()-1 -> 22 | B23: =CONCATENATE("Cod. Donaueschingen ",C23) -> Cod. Donaueschingen 105a | C23: 105a | D23: 202 | E23: =IF(COUNTIF('HSP-Abzug'!$A$2:$A$300,B23)=1,VLOOKUP(B23,'HSP-Abzug'!$A$3:$L$301,7,FALSE),"") -> HSP-b03c17a8-959d-34aa-87be-d2a332e55ed1 | F23: =IF(COUNTIF('HSP-Abzug'!$A$2:$A$300,B23)=1,VLOOKUP(B23,'HSP-Abzug'!$A$3:$L$301,11,FALSE),"") -> https://resolver.staatsbibliothek-berlin.de/HSP0005398500000000 | G23: =IF(COUNTIF('HSP-Abzug'!$A$2:$A$300,B23)=1,VLOOKUP(B23,'HSP-Abzug'!$A$3:$L$301,10,FALSE),"") -> HSP-84d08aa6-8229-32ce-87e8-19c70287dd6d | H23: =IF(COUNTIF('HSP-Abzug 2'!$A$2:$A$300,B23)=1,VLOOKUP(B23,'HSP-Abzug 2'!$A$3:$P$301,9,FALSE),"") -> https://resolver.staatsbibliothek-berlin.de/HSP00062F9B00000000
A24: =ROW()-1 -> 23 | B24: =CONCATENATE("Cod. Donaueschingen ",C24) -> Cod. Donaueschingen 105b | C24: 105b | D24: 202 | E24: =IF(COUNTIF('HSP-Abzug'!$A$2:$A$300,B24)=1,VLOOKUP(B24,'HSP-Abzug'!$A$3:$L$301,7,FALSE),"") -> HSP-123c157d-d700-3442-abb2-41352424f203 | F24: =IF(COUNTIF('HSP-Abzug'!$A$2:$A$300,B24)=1,VLOOKUP(B24,'HSP-Abzug'!$A$3:$L$301,11,FALSE),"") -> https://resolver.staatsbibliothek-berlin.de/HSP0005398600000000 | G24: =IF(COUNTIF('HSP-Abzug'!$A$2:$A$300,B24)=1,VLOOKUP(B24,'HSP-Abzug'!$A$3:$L$301,10,FALSE),"") -> HSP-0f117a9f-b856-3a17-a424-4c15bc3ac4b3 | H24: =IF(COUNTIF('HSP-Abzug 2'!$A$2:$A$300,B24)=1,VLOOKUP(B24,'HSP-Abzug 2'!$A$3:$P$301,9,FALSE),"") -> https://resolver.staatsbibliothek-berlin.de/HSP00062F9A00000000
A25: =ROW()-1 -> 24 | B25: =CONCATENATE("Cod. Donaueschingen ",C25) -> Cod. Donaueschingen 105c | C25: 105c | D25: 202 | E25: =IF(COUNTIF('HSP-Abzug'!$A$2:$A$300,B25)=1,VLOOKUP(B25,'HSP-Abzug'!$A$3:$L$301,7,FALSE),"") -> HSP-9d4c8ee0-be22-3b58-b547-534bc8c94b60 | F25: =IF(COUNTIF('HSP-Abzug'!$A$2:$A$300,B25)=1,VLOOKUP(B25,'HSP-Abzug'!$A$3:$L$301,11,FALSE),"") -> https://resolver.staatsbibliothek-berlin.de/HSP0005398700000000 | G25: =IF(COUNTIF('HSP-Abzug'!$A$2:$A$300,B25)=1,VLOOKUP(B25,'HSP-Abzug'!$A$3:$L$301,10,FALSE),"") -> HSP-919868b3-5792-34bb-91e0-9a299321870b | H25: =IF(COUNTIF('HSP-Abzug 2'!$A$2:$A$300,B25)=1,VLOOKUP(B25,'HSP-Abzug 2'!$A$3:$P$301,9,FALSE),"") -> https://resolver.staatsbibliothek-berlin.de/HSP00062F9D00000000
A26: =ROW()-1 -> 25 | B26: =CONCATENATE("Cod. Donaueschingen ",C26) -> Cod. Donaueschingen 106 | C26: 106 | D26: 183, 25 | E26: =IF(COUNTIF('HSP-Abzug'!$A$2:$A$300,B26)=1,VLOOKUP(B26,'HSP-Abzug'!$A$3:$L$301,7,FALSE),"") -> HSP-6c930a96-775e-3a48-80e6-596a1db0e274 | F26: =IF(COUNTIF('HSP-Abzug'!$A$2:$A$300,B26)=1,VLOOKUP(B26,'HSP-Abzug'!$A$3:$L$301,11,FALSE),"") -> https://resolver.staatsbibliothek-berlin.de/HSP0005398800000000 | G26: =IF(COUNTIF('HSP-Abzug'!$A$2:$A$300,B26)=1,VLOOKUP(B26,'HSP-Abzug'!$A$3:$L$301,10,FALSE),"") -> HSP-316cca2d-b0da-367e-9c40-dccd11c95baf | H26: =IF(COUNTIF('HSP-Abzug 2'!$A$2:$A$300,B26)=1,VLOOKUP(B26,'HSP-Abzug 2'!$A$3:$P$301,9,FALSE),"") -> https://resolver.staatsbibliothek-berlin.de/HSP00062F5200000000
A27: =ROW()-1 -> 26 | B27: =CONCATENATE("Cod. Donaueschingen ",C27) -> Cod. Donaueschingen 107 | C27: 107 | D27: 181 | E27: =IF(COUNTIF('HSP-Abzug'!$A$2:$A$300,B27)=1,VLOOKUP(B27,'HSP-Abzug'!$A$3:$L$301,7,FALSE),"") -> HSP-8b29460e-0e02-3c1a-962d-7ffaf070b7f4 | F27: =IF(COUNTIF('HSP-Abzug'!$A$2:$A$300,B27)=1,VLOOKUP(B27,'HSP-Abzug'!$A$3:$L$301,11,FALSE),"") -> https://resolver.staatsbibliothek-berlin.de/HSP0005398900000000 | G27: =IF(COUNTIF('HSP-Abzug'!$A$2:$A$300,B27)=1,VLOOKUP(B27,'HSP-Abzug'!$A$3:$L$301,10,FALSE),"") -> HSP-020577c8-bfe2-34eb-92fa-34d5e83b354e | H27: =IF(COUNTIF('HSP-Abzug 2'!$A$2:$A$300,B27)=1,VLOOKUP(B27,'HSP-Abzug 2'!$A$3:$P$301,9,FALSE),"") -> https://resolver.staatsbibliothek-berlin.de/HSP00062F5900000000
A28: =ROW()-1 -> 27 | B28: =CONCATENATE("Cod. Donaueschingen ",C28) -> Cod. Donaueschingen 109 | C28: 109 | D28: 195 | E28: =IF(COUNTIF('HSP-Abzug'!$A$2:$A$300,B28)=1,VLOOKUP(B28,'HSP-Abzug'!$A$3:$L$301,7,FALSE),"") -> HSP-d82573c4-e0c7-37dc-9208-ed9ee10f245d | F28: =IF(COUNTIF('HSP-Abzug'!$A$2:$A$300,B28)=1,VLOOKUP(B28,'HSP-Abzug'!$A$3:$L$301,11,FALSE),"") -> https://resolver.staatsbibliothek-berlin.de/HSP0005398B00000000 | G28: =IF(COUNTIF('HSP-Abzug'!$A$2:$A$300,B28)=1,VLOOKUP(B28,'HSP-Abzug'!$A$3:$L$301,10,FALSE),"") -> HSP-6eed1555-f5e0-3504-9c7d-d8531e1ef34c | H28: =IF(COUNTIF('HSP-Abzug 2'!$A$2:$A$300,B28)=1,VLOOKUP(B28,'HSP-Abzug 2'!$A$3:$P$301,9,FALSE),"") -> https://resolver.staatsbibliothek-berlin.de/HSP00062F5C00000000
A29: =ROW()-1 -> 28 | B29: =CONCATENATE("Cod. Donaueschingen ",C29) -> Cod. Donaueschingen 110 | C29: 110 | D29: 87 | E29: =IF(COUNTIF('HSP-Abzug'!$A$2:$A$300,B29)=1,VLOOKUP(B29,'HSP-Abzug'!$A$3:$L$301,7,FALSE),"") -> HSP-2b779d49-b34a-3564-8e04-65a09a82b257 | F29: =IF(COUNTIF('HSP-Abzug'!$A$2:$A$300,B29)=1,VLOOKUP(B29,'HSP-Abzug'!$A$3:$L$301,11,FALSE),"") -> https://resolver.staatsbibliothek-berlin.de/HSP0005398D00000000 | G29: =IF(COUNTIF('HSP-Abzug'!$A$2:$A$300,B29)=1,VLOOKUP(B29,'HSP-Abzug'!$A$3:$L$301,10,FALSE),"") -> HSP-b7624685-1c27-3826-9d46-55ff9b0d50c7 | H29: =IF(COUNTIF('HSP-Abzug 2'!$A$2:$A$300,B29)=1,VLOOKUP(B29,'HSP-Abzug 2'!$A$3:$P$301,9,FALSE),"") -> https://resolver.staatsbibliothek-berlin.de/HSP00062FA200000000
A30: =ROW()-1 -> 29 | B30: =CONCATENATE("Cod. Donaueschingen ",C30) -> Cod. Donaueschingen 111a | C30: 111a | D30: 180, 184 | E30: =IF(COUNTIF('HSP-Abzug'!$A$2:$A$300,B30)=1,VLOOKUP(B30,'HSP-Abzug'!$A$3:$L$301,7,FALSE),"") -> HSP-c6afe163-f032-3b3f-a586-6cbfe17d9310 | F30: =IF(COUNTIF('HSP-Abzug'!$A$2:$A$300,B30)=1,VLOOKUP(B30,'HSP-Abzug'!$A$3:$L$301,11,FALSE),"") -> https://resolver.staatsbibliothek-berlin.de/HSP0005398E00000000 | G30: =IF(COUNTIF('HSP-Abzug'!$A$2:$A$300,B30)=1,VLOOKUP(B30,'HSP-Abzug'!$A$3:$L$301,10,FALSE),"") -> HSP-9f5115d9-bcd7-327b-a7c0-d2437bc72e5e | H30: =IF(COUNTIF('HSP-Abzug 2'!$A$2:$A$300,B30)=1,VLOOKUP(B30,'HSP-Abzug 2'!$A$3:$P$301,9,FALSE),"") -> https://resolver.staatsbibliothek-berlin.de/HSP00062FA400000000
A31: =ROW()-1 -> 30 | B31: =CONCATENATE("Cod. Donaueschingen ",C31) -> Cod. Donaueschingen 112 | C31: 112 | D31: 182 | E31: =IF(COUNTIF('HSP-Abzug'!$A$2:$A$300,B31)=1,VLOOKUP(B31,'HSP-Abzug'!$A$3:$L$301,7,FALSE),"") -> HSP-d1621618-141f-314e-b596-d50703f7bb42 | F31: =IF(COUNTIF('HSP-Abzug'!$A$2:$A$300,B31)=1,VLOOKUP(B31,'HSP-Abzug'!$A$3:$L$301,11,FALSE),"") -> https://resolver.staatsbibliothek-berlin.de/HSP0005399000000000 | G31: =IF(COUNTIF('HSP-Abzug'!$A$2:$A$300,B31)=1,VLOOKUP(B31,'HSP-Abzug'!$A$3:$L$301,10,FALSE),"") -> HSP-aec3d7af-3a62-3dd1-bca8-625a79aea451 | H31: =IF(COUNTIF('HSP-Abzug 2'!$A$2:$A$300,B31)=1,VLOOKUP(B31,'HSP-Abzug 2'!$A$3:$P$301,9,FALSE),"") -> #N/A
A32: =ROW()-1 -> 31 | B32: =CONCATENATE("Cod. Donaueschingen ",C32) -> Cod. Donaueschingen 113 | C32: 113 | D32: 189 | E32: =IF(COUNTIF('HSP-Abzug'!$A$2:$A$300,B32)=1,VLOOKUP(B32,'HSP-Abzug'!$A$3:$L$301,7,FALSE),"") -> HSP-9f926ebf-10bb-3d20-88e0-9c8c506be721 | F32: =IF(COUNTIF('HSP-Abzug'!$A$2:$A$300,B32)=1,VLOOKUP(B32,'HSP-Abzug'!$A$3:$L$301,11,FALSE),"") -> https://resolver.staatsbibliothek-berlin.de/HSP0005399100000000 | G32: =IF(COUNTIF('HSP-Abzug'!$A$2:$A$300,B32)=1,VLOOKUP(B32,'HSP-Abzug'!$A$3:$L$301,10,FALSE),"") -> HSP-460c4b85-3c12-3402-98c2-60c2f8f34eb9 | H32: =IF(COUNTIF('HSP-Abzug 2'!$A$2:$A$300,B32)=1,VLOOKUP(B32,'HSP-Abzug 2'!$A$3:$P$301,9,FALSE),"") -> https://resolver.staatsbibliothek-berlin.de/HSP00062FAF00000000
A33: =ROW()-1 -> 32 | B33: =CONCATENATE("Cod. Donaueschingen ",C33) -> Cod. Donaueschingen 114 | C33: 114 | D33: 216 | E33: =IF(COUNTIF('HSP-Abzug'!$A$2:$A$300,B33)=1,VLOOKUP(B33,'HSP-Abzug'!$A$3:$L$301,7,FALSE),"") -> HSP-9ac7779f-d662-34a5-a8f8-6bccf87b549b | F33: =IF(COUNTIF('HSP-Abzug'!$A$2:$A$300,B33)=1,VLOOKUP(B33,'HSP-Abzug'!$A$3:$L$301,11,FALSE),"") -> https://resolver.staatsbibliothek-berlin.de/HSP0005399200000000 | G33: =IF(COUNTIF('HSP-Abzug'!$A$2:$A$300,B33)=1,VLOOKUP(B33,'HSP-Abzug'!$A$3:$L$301,10,FALSE),"") -> HSP-3c1cb820-a9ad-388c-b79f-3deef206961c | H33: =IF(COUNTIF('HSP-Abzug 2'!$A$2:$A$300,B33)=1,VLOOKUP(B33,'HSP-Abzug 2'!$A$3:$P$301,9,FALSE),"") -> https://resolver.staatsbibliothek-berlin.de/HSP00062FA500000000
A34: =ROW()-1 -> 33 | B34: =CONCATENATE("Cod. Donaueschingen ",C34) -> Cod. Donaueschingen 115 | C34: 115 | D34: 237, 238, 239 | E34: =IF(COUNTIF('HSP-Abzug'!$A$2:$A$300,B34)=1,VLOOKUP(B34,'HSP-Abzug'!$A$3:$L$301,7,FALSE),"") -> HSP-4016433d-33c4-30b2-979a-4d4d220fad94 | F34: =IF(COUNTIF('HSP-Abzug'!$A$2:$A$300,B34)=1,VLOOKUP(B34,'HSP-Abzug'!$A$3:$L$301,11,FALSE),"") -> https://resolver.staatsbibliothek-berlin.de/HSP0005399300000000 | G34: =IF(COUNTIF('HSP-Abzug'!$A$2:$A$300,B34)=1,VLOOKUP(B34,'HSP-Abzug'!$A$3:$L$301,10,FALSE),"") -> HSP-442630a1-d1e0-3160-a8c4-bd5a4a730bc7 | H34: =IF(COUNTIF('HSP-Abzug 2'!$A$2:$A$300,B34)=1,VLOOKUP(B34,'HSP-Abzug 2'!$A$3:$P$301,9,FALSE),"") -> https://resolver.staatsbibliothek-berlin.de/HSP00062F4E00000000
A35: =ROW()-1 -> 34 | B35: =CONCATENATE("Cod. Donaueschingen ",C35) -> Cod. Donaueschingen 116 | C35: 116 | D35: 31 | E35: =IF(COUNTIF('HSP-Abzug'!$A$2:$A$300,B35)=1,VLOOKUP(B35,'HSP-Abzug'!$A$3:$L$301,7,FALSE),"") -> HSP-c7be4edd-9935-3942-a1ba-615bd68da72a | F35: =IF(COUNTIF('HSP-Abzug'!$A$2:$A$300,B35)=1,VLOOKUP(B35,'HSP-Abzug'!$A$3:$L$301,11,FALSE),"") -> https://resolver.staatsbibliothek-berlin.de/HSP0005399400000000 | G35: =IF(COUNTIF('HSP-Abzug'!$A$2:$A$300,B35)=1,VLOOKUP(B35,'HSP-Abzug'!$A$3:$L$301,10,FALSE),"") -> HSP-3d089ce7-6ef5-37e1-9134-51536f5b633e | H35: =IF(COUNTIF('HSP-Abzug 2'!$A$2:$A$300,B35)=1,VLOOKUP(B35,'HSP-Abzug 2'!$A$3:$P$301,9,FALSE),"") -> https://resolver.staatsbibliothek-berlin.de/HSP00062F4D00000000
A36: =ROW()-1 -> 35 | B36: =CONCATENATE("Cod. Donaueschingen ",C36) -> Cod. Donaueschingen 118 | C36: 118 | D36: 241 | E36: =IF(COUNTIF('HSP-Abzug'!$A$2:$A$300,B36)=1,VLOOKUP(B36,'HSP-Abzug'!$A$3:$L$301,7,FALSE),"") -> HSP-8a28a11c-1699-3f3d-a959-981cbb7b2352 | F36: =IF(COUNTIF('HSP-Abzug'!$A$2:$A$300,B36)=1,VLOOKUP(B36,'HSP-Abzug'!$A$3:$L$301,11,FALSE),"") -> https://resolver.staatsbibliothek-berlin.de/HSP0005399600000000 | G36: =IF(COUNTIF('HSP-Abzug'!$A$2:$A$300,B36)=1,VLOOKUP(B36,'HSP-Abzug'!$A$3:$L$301,10,FALSE),"") -> HSP-f5ab6df3-192f-32d4-a00a-a7b59565447c | H36: =IF(COUNTIF('HSP-Abzug 2'!$A$2:$A$300,B36)=1,VLOOKUP(B36,'HSP-Abzug 2'!$A$3:$P$301,9,FALSE),"") -> https://resolver.staatsbibliothek-berlin.de/HSP00062F8700000000
A37: =ROW()-1 -> 36 | B37: =CONCATENATE("Cod. Donaueschingen ",C37) -> Cod. Donaueschingen 119 | C37: 119 | D37: 245 | E37: =IF(COUNTIF('HSP-Abzug'!$A$2:$A$300,B37)=1,VLOOKUP(B37,'HSP-Abzug'!$A$3:$L$301,7,FALSE),"") -> HSP-e03bca77-9acf-3204-9121-83cc03d95cd5 | F37: =IF(COUNTIF('HSP-Abzug'!$A$2:$A$300,B37)=1,VLOOKUP(B37,'HSP-Abzug'!$A$3:$L$301,11,FALSE),"") -> https://resolver.staatsbibliothek-berlin.de/HSP0005399700000000 | G37: =IF(COUNTIF('HSP-Abzug'!$A$2:$A$300,B37)=1,VLOOKUP(B37,'HSP-Abzug'!$A$3:$L$301,10,FALSE),"") -> HSP-efdbae03-c961-3590-a87a-ac5be2285366 | H37: =IF(COUNTIF('HSP-Abzug 2'!$A$2:$A$300,B37)=1,VLOOKUP(B37,'HSP-Abzug 2'!$A$3:$P$301,9,FALSE),"") -> https://resolver.staatsbibliothek-berlin.de/HSP00062F8800000000
A38: =ROW()-1 -> 37 | B38: =CONCATENATE("Cod. Donaueschingen ",C38) -> Cod. Donaueschingen 120 | C38: 120 | D38: 263 | E38: =IF(COUNTIF('HSP-Abzug'!$A$2:$A$300,B38)=1,VLOOKUP(B38,'HSP-Abzug'!$A$3:$L$301,7,FALSE),"") -> HSP-8f8428dc-9cb1-35dd-9c20-fdfab0749655 | F38: =IF(COUNTIF('HSP-Abzug'!$A$2:$A$300,B38)=1,VLOOKUP(B38,'HSP-Abzug'!$A$3:$L$301,11,FALSE),"") -> https://resolver.staatsbibliothek-berlin.de/HSP0005399800000000 | G38: =IF(COUNTIF('HSP-Abzug'!$A$2:$A$300,B38)=1,VLOOKUP(B38,'HSP-Abzug'!$A$3:$L$301,10,FALSE),"") -> HSP-013575d7-38c1-3442-a52d-186d958881f0 | H38: =IF(COUNTIF('HSP-Abzug 2'!$A$2:$A$300,B38)=1,VLOOKUP(B38,'HSP-Abzug 2'!$A$3:$P$301,9,FALSE),"") -> https://resolver.staatsbibliothek-berlin.de/HSP00062F8400000000
A39: =ROW()-1 -> 38 | B39: =CONCATENATE("Cod. Donaueschingen ",C39) -> Cod. Donaueschingen 121 | C39: 121 | D39: 196 | E39: =IF(COUNTIF('HSP-Abzug'!$A$2:$A$300,B39)=1,VLOOKUP(B39,'HSP-Abzug'!$A$3:$L$301,7,FALSE),"") -> HSP-6d692352-5040-3daf-92e6-e10e6dadb784 | F39: =IF(COUNTIF('HSP-Abzug'!$A$2:$A$300,B39)=1,VLOOKUP(B39,'HSP-Abzug'!$A$3:$L$301,11,FALSE),"") -> https://resolver.staatsbibliothek-berlin.de/HSP0005399900000000 | G39: =IF(COUNTIF('HSP-Abzug'!$A$2:$A$300,B39)=1,VLOOKUP(B39,'HSP-Abzug'!$A$3:$L$301,10,FALSE),"") -> HSP-abdb0969-3e0c-3730-8035-58ddbd4444c9 | H39: =IF(COUNTIF('HSP-Abzug 2'!$A$2:$A$300,B39)=1,VLOOKUP(B39,'HSP-Abzug 2'!$A$3:$P$301,9,FALSE),"") -> https://resolver.staatsbibliothek-berlin.de/HSP00062FBA00000000
A40: =ROW()-1 -> 39 | B40: =CONCATENATE("Cod. Donaueschingen ",C40) -> Cod. Donaueschingen 129 | C40: 129 | D40: 205 | E40: =IF(COUNTIF('HSP-Abzug'!$A$2:$A$300,B40)=1,VLOOKUP(B40,'HSP-Abzug'!$A$3:$L$301,7,FALSE),"") -> HSP-025a0302-cbea-3a34-9c20-592e9c885e7b | F40: =IF(COUNTIF('HSP-Abzug'!$A$2:$A$300,B40)=1,VLOOKUP(B40,'HSP-Abzug'!$A$3:$L$301,11,FALSE),"") -> https://resolver.staatsbibliothek-berlin.de/HSP0005399B00000000 | G40: =IF(COUNTIF('HSP-Abzug'!$A$2:$A$300,B40)=1,VLOOKUP(B40,'HSP-Abzug'!$A$3:$L$301,10,FALSE),"") -> HSP-12f7558a-ffd8-3eba-ab30-99ff1ba7fea5 | H40: =IF(COUNTIF('HSP-Abzug 2'!$A$2:$A$300,B40)=1,VLOOKUP(B40,'HSP-Abzug 2'!$A$3:$P$301,9,FALSE),"") -> https://resolver.staatsbibliothek-berlin.de/HSP00062F5800000000
...

Sheet HSP-Abzug
A1: Signatur | B1: Sortierschlüssel | C1: Besitzende Einrichtung | D1: Ort | E1: Mit Beschreibungen | F1: Mit Digitalisat | G1: HSP-ID-Kulturobjekt | H1: GND-ID | I1: Registrierungsdatum | J1: HSP-ID-Beschreibung | K1: PURL | L1: Kerndaten befüllt
A2: Cod. Donaueschingen 100 | C2: Badische Landesbibliothek | D2: Karlsruhe | E2: JA | F2: JA | G2: HSP-2af49c90-bf93-3042-b68d-1ac59f7faefd | I2: 44895.881 | J2: HSP-080628d4-b0cd-3aa5-8b6f-b702ce608bf7 | K2: https://resolver.staatsbibliothek-berlin.de/HSP0005398000000000 | L2: AUTOMATISCH
A3: Cod. Donaueschingen 101 | C3: Badische Landesbibliothek | D3: Karlsruhe | E3: JA | F3: JA | G3: HSP-9595b803-f48f-3c82-b6f2-8332c772cb0d | I3: 44895.881 | J3: HSP-64fb7e18-e85d-3a8f-bc70-96578dc81061 | K3: https://resolver.staatsbibliothek-berlin.de/HSP0005398100000000 | L3: AUTOMATISCH
A4: Cod. Donaueschingen 102 | C4: Badische Landesbibliothek | D4: Karlsruhe | E4: JA | F4: JA | G4: HSP-b62c17d8-bb06-3d10-adbc-fccfe9d83e07 | I4: 44895.881 | J4: HSP-2b25de19-8d72-3812-8d5b-5f964da8adf8 | K4: https://resolver.staatsbibliothek-berlin.de/HSP0005398200000000 | L4: AUTOMATISCH
A5: Cod. Donaueschingen 103 | C5: Badische Landesbibliothek | D5: Karlsruhe | E5: JA | F5: JA | G5: HSP-3133e409-8a59-3b42-b433-1f285eb67042 | I5: 44895.881 | J5: HSP-2a154dfc-800a-3aee-8131-6cba2bce6d34 | K5: https://resolver.staatsbibliothek-berlin.de/HSP0005398300000000 | L5: AUTOMATISCH
A6: Cod. Donaueschingen 104 | C6: Badische Landesbibliothek | D6: Karlsruhe | E6: JA | F6: JA | G6: HSP-96a15530-bf95-375e-a6a9-e34efb79e8fb | I6: 44895.881 | J6: HSP-11d6b533-63f3-36bd-91aa-4a8d5ef766fd | K6: https://resolver.staatsbibliothek-berlin.de/HSP0005398400000000 | L6: AUTOMATISCH
A7: Cod. Donaueschingen 105a | C7: Badische Landesbibliothek | D7: Karlsruhe | E7: JA | F7: JA | G7: HSP-b03c17a8-959d-34aa-87be-d2a332e55ed1 | I7: 44895.881 | J7: HSP-84d08aa6-8229-32ce-87e8-19c70287dd6d | K7: https://resolver.staatsbibliothek-berlin.de/HSP0005398500000000 | L7: AUTOMATISCH
A8: Cod. Donaueschingen 105b | C8: Badische Landesbibliothek | D8: Karlsruhe | E8: JA | F8: JA | G8: HSP-123c157d-d700-3442-abb2-41352424f203 | I8: 44895.881 | J8: HSP-0f117a9f-b856-3a17-a424-4c15bc3ac4b3 | K8: https://resolver.staatsbibliothek-berlin.de/HSP0005398600000000 | L8: AUTOMATISCH
A9: Cod. Donaueschingen 105c | C9: Badische Landesbibliothek | D9: Karlsruhe | E9: JA | F9: JA | G9: HSP-9d4c8ee0-be22-3b58-b547-534bc8c94b60 | I9: 44895.881 | J9: HSP-919868b3-5792-34bb-91e0-9a299321870b | K9: https://resolver.staatsbibliothek-berlin.de/HSP0005398700000000 | L9: AUTOMATISCH
A10: Cod. Donaueschingen 106 | C10: Badische Landesbibliothek | D10: Karlsruhe | E10: JA | F10: JA | G10: HSP-6c930a96-775e-3a48-80e6-596a1db0e274 | I10: 44895.881 | J10: HSP-316cca2d-b0da-367e-9c40-dccd11c95baf | K10: https://resolver.staatsbibliothek-berlin.de/HSP0005398800000000 | L10: AUTOMATISCH
A11: Cod. Donaueschingen 107 | C11: Badische Landesbibliothek | D11: Karlsruhe | E11: JA | F11: JA | G11: HSP-8b29460e-0e02-3c1a-962d-7ffaf070b7f4 | I11: 44895.881 | J11: HSP-020577c8-bfe2-34eb-92fa-34d5e83b354e | K11: https://resolver.staatsbibliothek-berlin.de/HSP0005398900000000 | L11: AUTOMATISCH
A12: Cod. Donaueschingen 108 | C12: Badische Landesbibliothek | D12: Karlsruhe | E12: JA | F12: JA | G12: HSP-dd90c7ec-87e7-3716-a123-a3e987a52b55 | I12: 44895.881 | J12: HSP-a00afbf7-bae2-38a2-ba87-1759fe50a588 | K12: https://resolver.staatsbibliothek-berlin.de/HSP0005398A00000000 | L12: AUTOMATISCH
A13: Cod. Donaueschingen 109 | C13: Badische Landesbibliothek | D13: Karlsruhe | E13: JA | F13: JA | G13: HSP-d82573c4-e0c7-37dc-9208-ed9ee10f245d | I13: 44895.881 | J13: HSP-6eed1555-f5e0-3504-9c7d-d8531e1ef34c | K13: https://resolver.staatsbibliothek-berlin.de/HSP0005398B00000000 | L13: AUTOMATISCH
... A288: Cod. Donaueschingen D 2,2 | C288: Badische Landesbibliothek | D288: Karlsruhe | E288: JA | F288: NEIN | G288: HSP-c68a784e-6f52-3ec9-8602-8cf9af4aadcc | I288: 45705.507 | J288: HSP-c8c4fcfd-82f4-3cfd-8566-17b5503f7908 | K288: https://resolver.staatsbibliothek-berlin.de/HSP0006DF6100000000 | L288: AUTOMATISCH

Sheet HSP-Abzug 2
A1: Signatur | B1: Besitzende Einrichtung | C1: Ort | D1: Status | E1: HSP Publikationsdatum | F1: Beschreibungsautor:in | G1: HSP-ID-Beschreibung | H1: HSP-ID-Kulturobjekt | I1: HSP-PURL | J1: Letzte Änderung | K1: Erstellungsdatum | L1: Verwaltungstyp | M1: Aus gedrucktem Katalog | N1: Katalog ID | O1: Bearbeiter
A2: Cod. Donaueschingen 112 | B2: Badische Landesbibliothek | C2: Karlsruhe | D2: publiziert | E2: 46142.756 | F2: Eichenberger, Nicole | G2: HSP-aec3d7af-3a62-3dd1-bca8-625a79aea451 | H2: HSP-d1621618-141f-314e-b596-d50703f7bb42 | I2: https://resolver.staatsbibliothek-berlin.de/HSP00062F4C00000000 | J2: 8102025 | K2: 23042012 | L2: EXTERN | M2: nein | N2: 865 | O2: -
A3: Cod. Donaueschingen 116 | B3: Badische Landesbibliothek | C3: Karlsruhe | D3: publiziert | E3: 46142.756 | F3: Eichenberger, Nicole | G3: HSP-3d089ce7-6ef5-37e1-9134-51536f5b633e | H3: HSP-c7be4edd-9935-3942-a1ba-615bd68da72a | I3: https://resolver.staatsbibliothek-berlin.de/HSP00062F4D00000000 | J3: 8102025 | K3: 9052012 | L3: EXTERN | M3: nein | N3: 865 | O3: -
A4: Cod. Donaueschingen 142 | B4: Badische Landesbibliothek | C4: Karlsruhe | D4: publiziert | E4: 46142.756 | F4: org.apache.myfaces.view.facelets.component.UIRepeat@2db32431 | G4: HSP-c5104235-a720-3ff6-9eac-6e04ec765315 | H4: HSP-9bf09489-f82c-377a-9ca0-88fe0aaae195 | I4: https://resolver.staatsbibliothek-berlin.de/HSP00062F4F00000000 | J4: 8102025 | K4: 20082012 | L4: EXTERN | M4: nein | N4: 865 | O4: -
A5: Cod. Donaueschingen 115 | B5: Badische Landesbibliothek | C5: Karlsruhe | D5: publiziert | E5: 46142.756 | F5: Eichenberger, Nicole | G5: HSP-442630a1-d1e0-3160-a8c4-bd5a4a730bc7 | H5: HSP-4016433d-33c4-30b2-979a-4d4d220fad94 | I5: https://resolver.staatsbibliothek-berlin.de/HSP00062F4E00000000 | J5: 8102025 | K5: 20082012 | L5: EXTERN | M5: nein | N5: 865 | O5: -
A6: Cod. Donaueschingen 143 | B6: Badische Landesbibliothek | C6: Karlsruhe | D6: publiziert | E6: 46142.756 | F6: Eichenberger, Nicole | G6: HSP-44cdaf1e-8feb-3800-a704-945af4790d95 | H6: HSP-75128c7c-ff29-33af-bcb1-3c7811341c87 | I6: https://resolver.staatsbibliothek-berlin.de/HSP00062F5000000000 | J6: 8102025 | K6: 21082012 | L6: EXTERN | M6: nein | N6: 865 | O6: -
A7: Cod. Donaueschingen 104 | B7: Badische Landesbibliothek | C7: Karlsruhe | D7: publiziert | E7: 46142.756 | F7: Eichenberger, Nicole | G7: HSP-11d6b533-63f3-36bd-91aa-4a8d5ef766fd | H7: HSP-96a15530-bf95-375e-a6a9-e34efb79e8fb | I7: https://resolver.staatsbibliothek-berlin.de/HSP00062F5100000000 | J7: 8102025 | K7: 21082012 | L7: EXTERN | M7: nein | N7: 865 | O7: -
A8: Cod. Donaueschingen 106 | B8: Badische Landesbibliothek | C8: Karlsruhe | D8: publiziert | E8: 46142.756 | F8: Eichenberger, Nicole | G8: HSP-316cca2d-b0da-367e-9c40-dccd11c95baf | H8: HSP-6c930a96-775e-3a48-80e6-596a1db0e274 | I8: https://resolver.staatsbibliothek-berlin.de/HSP00062F5200000000 | J8: 21102025 | K8: 27082012 | L8: EXTERN | M8: nein | N8: 865 | O8: -
A9: Cod. Donaueschingen 94 | B9: Badische Landesbibliothek | C9: Karlsruhe | D9: publiziert | E9: 46142.756 | F9: org.apache.myfaces.view.facelets.component.UIRepeat@2db32431 | G9: HSP-0f040e59-61aa-37e7-91f0-1d589d9b7ba4 | H9: HSP-344ed4cd-0ae7-35e5-b8af-a15c841605a5 | I9: https://resolver.staatsbibliothek-berlin.de/HSP00062F5400000000 | J9: 8102025 | K9: 27082012 | L9: EXTERN | M9: nein | N9: 865 | O9: -
A10: Cod. Donaueschingen 140 | B10: Badische Landesbibliothek | C10: Karlsruhe | D10: publiziert | E10: 46142.756 | F10: Eichenberger, Nicole | G10: HSP-9df5a0d1-d1e2-3532-864e-f38b58144007 | H10: HSP-9e585e03-1165-3d80-bc4a-35129d70b7d9 | I10: https://resolver.staatsbibliothek-berlin.de/HSP00062F5300000000 | J10: 8102025 | K10: 27082012 | L10: EXTERN | M10: nein | N10: 865 | O10: -
A11: Cod. Donaueschingen 117 | B11: Badische Landesbibliothek | C11: Karlsruhe | D11: publiziert | E11: 46142.756 | F11: Eichenberger, Nicole | G11: HSP-1b322012-7251-3d38-9338-72acb2bb30d0 | H11: HSP-6542ec5c-cf83-326d-97ae-105ce67e3756 | I11: https://resolver.staatsbibliothek-berlin.de/HSP00062F5600000000 | J11: 8102025 | K11: 27082012 | L11: EXTERN | M11: nein | N11: 865 | O11: -
A12: Cod. Donaueschingen 148 | B12: Badische Landesbibliothek | C12: Karlsruhe | D12: publiziert | E12: 46142.756 | F12: org.apache.myfaces.view.facelets.component.UIRepeat@2db32431 | G12: HSP-4a75815a-e28c-3de8-9e4e-1607798656d4 | H12: HSP-491f52f3-a36e-3472-af35-a6be58ec1ca9 | I12: https://resolver.staatsbibliothek-berlin.de/HSP00062F5500000000 | J12: 8102025 | K12: 27082012 | L12: EXTERN | M12: nein | N12: 865 | O12: -
A13: Cod. Donaueschingen 64 | B13: Badische Landesbibliothek | C13: Karlsruhe | D13: publiziert | E13: 46142.756 | F13: Mackert, Christoph | G13: HSP-b4730138-f8e7-35e2-8c1a-948a6e46f13e | H13: HSP-31655ad3-cde6-3c7d-b0a6-dff36cb6843e | I13: https://resolver.staatsbibliothek-berlin.de/HSP00062F5700000000 | J13: 8102025 | K13: 19092012 | L13: EXTERN | M13: nein | N13: 865 | O13: -
... A216: Cod. Donaueschingen 481 | B216: Badische Landesbibliothek | C216: Karlsruhe | D216: publiziert | E216: 46240.668 | F216: Sturm, Katrin | G216: HSP-a41ad124-d318-390c-b134-39c6b89bc0fa | H216: HSP-e318874a-8535-3665-9036-c5c666aceb05 | I216: https://resolver.staatsbibliothek-berlin.de/HSP000675C400000000 | J216: 10112025 | K216: 3112022 | L216: EXTERN | M216: nein | N216: 865 | O216: -
A217: Cod. Donaueschingen 635 | B217: Badische Landesbibliothek | C217: Karlsruhe | D217: publiziert | E217: 46240.389 | F217: Schaudeck, Franziska | G217: HSP-a1427720-e465-341b-b1bd-375ad61c6134 | H217: HSP-788a00af-0518-33c0-bba2-4bdaa2047f3d | I217: https://resolver.staatsbibliothek-berlin.de/HSP0006820F00000000 | J217: 13072026 | K217: 23022023 | L217: EXTERN | M217: nein | O217: -
A218: Cod. Donaueschingen 641 | B218: Badische Landesbibliothek | C218: Karlsruhe | D218: publiziert | E218: 46240.389 | F218: Schaudeck, Franziska | G218: HSP-e54e3daf-4cb9-302a-8d38-07dcf5cf13fe | H218: HSP-24b55477-f7d1-3727-9f52-d8cae9fc9a04 | I218: https://resolver.staatsbibliothek-berlin.de/HSP0006821300000000 | J218: 13072026 | K218: 23022023 | L218: EXTERN | M218: nein | O218: -
A219: Cod. Donaueschingen 606 | B219: Badische Landesbibliothek | C219: Karlsruhe | D219: publiziert | E219: 46240.389 | F219: Schaudeck, Franziska | G219: HSP-a9c9e358-1efa-3c40-8723-15915662fa0c | H219: HSP-ff88cb7a-85ec-34be-bff8-92bbab395abf | I219: https://resolver.staatsbibliothek-berlin.de/HSP0006821000000000 | J219: 6082026 | K219: 23022023 | L219: EXTERN | M219: nein | O219: -
A220: Cod. Donaueschingen C III b 10 | B220: Badische Landesbibliothek | C220: Karlsruhe | D220: publiziert | E220: 46240.389 | F220: Schaudeck, Franziska | G220: HSP-5d188cea-be10-3445-9819-5281a314d86e | H220: HSP-134849d0-9e56-361b-8cc6-54bd223678dc | I220: https://resolver.staatsbibliothek-berlin.de/HSP0006821A00000000 | J220: 13072026 | K220: 23022023 | L220: EXTERN | M220: nein | O220: -
A221: Cod. Donaueschingen 642 | B221: Badische Landesbibliothek | C221: Karlsruhe | D221: publiziert | E221: 46240.389 | F221: Schaudeck, Franziska | G221: HSP-b4d038df-5158-3f1a-9432-a9058d862a80 | H221: HSP-51477140-a269-3ca5-84a2-50ad9ecf2862 | I221: https://resolver.staatsbibliothek-berlin.de/HSP0006821400000000 | J221: 13072026 | K221: 23022023 | L221: EXTERN | M221: nein | O221: -
A222: Cod. Donaueschingen 607a | B222: Badische Landesbibliothek | C222: Karlsruhe | D222: publiziert | E222: 46240.389 | F222: Schaudeck, Franziska | G222: HSP-225e64b5-4ac2-3094-8775-5598e5e86379 | H222: HSP-dfc904cd-bdd0-3e9d-9b02-76e589aa419c | I222: https://resolver.staatsbibliothek-berlin.de/HSP0006821100000000 | J222: 13072026 | K222: 23022023 | L222: EXTERN | M222: nein | O222: -
A223: Cod. Donaueschingen C III b 1 | B223: Badische Landesbibliothek | C223: Karlsruhe | D223: publiziert | E223: 46240.389 | F223: Schaudeck, Franziska | G223: HSP-c5f22e95-8446-30fe-849d-90d8848e42c4 | H223: HSP-d1dc28bc-a139-3810-bc9c-e327e8e45741 | I223: https://resolver.staatsbibliothek-berlin.de/HSP0006821500000000 | J223: 6082026 | K223: 23022023 | L223: EXTERN | M223: nein | O223: -
A224: Cod. Donaueschingen 636 | B224: Badische Landesbibliothek | C224: Karlsruhe | D224: publiziert | E224: 46240.389 | F224: Schaudeck, Franziska | G224: HSP-86bc9514-e457-33e7-8b29-2c9d274a621d | H224: HSP-a9f02419-2f60-3ca7-9656-b0f404852253 | I224: https://resolver.staatsbibliothek-berlin.de/HSP0006821700000000 | J224: 14012024 | K224: 23022023 | L224: EXTERN | M224: nein | O224: -
A225: Cod. Donaueschingen C III b 9 | B225: Badische Landesbibliothek | C225: Karlsruhe | D225: publiziert | E225: 46240.389 | F225: Schaudeck, Franziska | G225: HSP-9c0dca66-48ba-3bb3-8439-bbc491278820 | H225: HSP-8e4475f1-2dfc-3594-864d-4d895c4e4851 | I225: https://resolver.staatsbibliothek-berlin.de/HSP0006821900000000 | J225: 14012024 | K225: 23022023 | L225: EXTERN | M225: nein | O225: -
A226: Cod. Donaueschingen C III b 7 | B226: Badische Landesbibliothek | C226: Karlsruhe | D226: publiziert | E226: 46240.389 | F226: Schaudeck, Franziska | G226: HSP-35d444ba-9afd-316d-8488-6cc9e275077d | H226: HSP-fc80226b-e5b9-3569-a952-e52d9e0eb39b | I226: https://resolver.staatsbibliothek-berlin.de/HSP0006821800000000 | J226: 14012024 | K226: 23022023 | L226: EXTERN | M226: nein | O226: -
A227: Cod. Donaueschingen 607b | B227: Badische Landesbibliothek | C227: Karlsruhe | D227: publiziert | E227: 46240.389 | F227: Schaudeck, Franziska | G227: HSP-25504f9b-dda5-345b-946b-132888ae66bf | H227: HSP-5b0902f3-7bb4-3c49-acab-478656a7d79a | I227: https://resolver.staatsbibliothek-berlin.de/HSP0006821200000000 | J227: 13072026 | K227: 23022023 | L227: EXTERN | M227: nein | O227: -
A228: Cod. Donaueschingen C III b 12 | B228: Badische Landesbibliothek | C228: Karlsruhe | D228: publiziert | E228: 46240.389 | F228: Schaudeck, Franziska | G228: HSP-06f86371-6a7a-31be-a776-af10a2ee2a6d | H228: HSP-36ea09c3-35ce-387c-b1db-6aa943f07988 | I228: https://resolver.staatsbibliothek-berlin.de/HSP0006821B00000000 | J228: 14012024 | K228: 23022023 | L228: EXTERN | M228: nein | O228: -
... A246: Cod. Donaueschingen 748 | B246: Badische Landesbibliothek | C246: Karlsruhe | D246: publiziert | E246: 46240.389 | F246: Schaudeck, Franziska | G246: HSP-9c5fe88f-4519-3b0d-8531-adc7de45271f | H246: HSP-9c6160b9-43c9-330b-97b3-63b6947398ae | I246: https://resolver.staatsbibliothek-berlin.de/HSP0006822500000000 | J246: 13072026 | K246: 1032023 | L246: EXTERN | M246: nein | O246: -
A247: Cod. Donaueschingen 483 | B247: Badische Landesbibliothek | C247: Karlsruhe | D247: publiziert | E247: 46240.668 | F247: Sturm, Katrin | G247: HSP-58b3e4b5-cf66-3db2-9348-3243b0d65f18 | H247: HSP-3521ac28-2d99-327f-b421-29af9cd3f47d | I247: https://resolver.staatsbibliothek-berlin.de/HSP0006DCF200000000 | J247: 3112025 | K247: 25072024 | L247: EXTERN | M247: nein | N247: 865 | O247: -
A248: Cod. Donaueschingen 691 | B248: Badische Landesbibliothek | C248: Karlsruhe | D248: publiziert | E248: 46240.668 | F248: org.apache.myfaces.view.facelets.component.UIRepeat@2db32431 | G248: HSP-366e2fa6-3d00-3da4-9e90-9d90a88c5e26 | H248: HSP-847dd3cc-9415-3b88-9b6d-2c1934ca43d9 | I248: https://resolver.staatsbibliothek-berlin.de/HSP0006DF7400000000 | J248: 3112025 | K248: 10012025 | L248: EXTERN | M248: nein | N248: 865 | O248: -
A249: Cod. Donaueschingen 746 | B249: Badische Landesbibliothek | C249: Karlsruhe | D249: publiziert | E249: 46240.668 | F249: org.apache.myfaces.view.facelets.component.UIRepeat@2db32431 | G249: HSP-65103f14-d61d-3f71-9412-73c0081658f7 | H249: HSP-555ed29d-bcf2-3296-a1d1-ea9cb92b65f5 | I249: https://resolver.staatsbibliothek-berlin.de/HSP0006DF7200000000 | J249: 27102025 | K249: 13012025 | L249: EXTERN | M249: nein | N249: 865 | O249: -
A250: Cod. Donaueschingen D 10b | B250: Badische Landesbibliothek | C250: Karlsruhe | D250: publiziert | E250: 46240.668 | F250: org.apache.myfaces.view.facelets.component.UIRepeat@2db32431 | G250: HSP-0b53384f-192c-3ce6-951a-f4c165ab93be | H250: HSP-47a236b9-6b83-3d0b-a7ba-58bcf15a4808 | I250: https://resolver.staatsbibliothek-berlin.de/HSP0006DF7900000000 | J250: 27102025 | K250: 13012025 | L250: EXTERN | M250: nein | N250: 865 | O250: -
A251: Cod. Donaueschingen 745 | B251: Badische Landesbibliothek | C251: Karlsruhe | D251: publiziert | E251: 46240.668 | F251: org.apache.myfaces.view.facelets.component.UIRepeat@2db32431 | G251: HSP-1f2adc38-8654-3f23-bdba-903c5013ce06 | H251: HSP-6e4ed855-b4f8-3386-9fbb-a3ccd0410a42 | I251: https://resolver.staatsbibliothek-berlin.de/HSP0006DF7000000000 | J251: 3022026 | K251: 13012025 | L251: EXTERN | M251: nein | N251: 865 | O251: -
A252: Cod. Donaueschingen 830 | B252: Badische Landesbibliothek | C252: Karlsruhe | D252: publiziert | E252: 46240.668 | F252: org.apache.myfaces.view.facelets.component.UIRepeat@2db32431 | G252: HSP-276e7fca-b7d4-316e-9cf1-457fcc6899f1 | H252: HSP-f27db9e4-defe-3c45-ac6a-f44afab68de7 | I252: https://resolver.staatsbibliothek-berlin.de/HSP0006DF7600000000 | J252: 18112025 | K252: 13012025 | L252: EXTERN | M252: nein | N252: 865 | O252: -
A253: Cod. Donaueschingen 740 | B253: Badische Landesbibliothek | C253: Karlsruhe | D253: publiziert | E253: 46240.668 | F253: org.apache.myfaces.view.facelets.component.UIRepeat@2db32431 | G253: HSP-5aaac491-ee7c-39eb-a3e3-a3d9d55b6318 | H253: HSP-e7d9d3ef-2580-3059-91c4-a54cb062b5d3 | I253: https://resolver.staatsbibliothek-berlin.de/HSP0006DF7100000000 | J253: 13022026 | K253: 13012025 | L253: EXTERN | M253: nein | N253: 865 | O253: -
A254: Cod. Donaueschingen 747 | B254: Badische Landesbibliothek | C254: Karlsruhe | D254: publiziert | E254: 46240.668 | F254: org.apache.myfaces.view.facelets.component.UIRepeat@2db32431 | G254: HSP-73ffebd1-3937-3893-9de7-4acd94b45eb9 | H254: HSP-8b0d8370-1ccd-394d-a4aa-9845300a8f1a | I254: https://resolver.staatsbibliothek-berlin.de/HSP0006DF7500000000 | J254: 18112025 | K254: 13012025 | L254: EXTERN | M254: nein | N254: 865 | O254: -
A255: Cod. Donaueschingen 738 | B255: Badische Landesbibliothek | C255: Karlsruhe | D255: publiziert | E255: 46240.668 | F255: org.apache.myfaces.view.facelets.component.UIRepeat@2db32431 | G255: HSP-806b719c-0ac3-3bec-9c97-178b5e44f8cd | H255: HSP-e799980d-e78f-313b-9354-ce341b84dd20 | I255: https://resolver.staatsbibliothek-berlin.de/HSP0006DF6B00000000 | J255: 17112025 | K255: 13012025 | L255: EXTERN | M255: nein | N255: 865 | O255: -
A256: Cod. Donaueschingen 741 | B256: Badische Landesbibliothek | C256: Karlsruhe | D256: publiziert | E256: 46240.668 | F256: org.apache.myfaces.view.facelets.component.UIRepeat@2db32431 | G256: HSP-82132307-fa72-311e-9b6a-9ec8206fb9b7 | H256: HSP-2ff70bf5-237a-33f2-87c4-974cfa9ff927 | I256: https://resolver.staatsbibliothek-berlin.de/HSP0006DF6D00000000 | J256: 17112025 | K256: 13012025 | L256: EXTERN | M256: nein | N256: 865 | O256: -
A257: Cod. Donaueschingen 743 | B257: Badische Landesbibliothek | C257: Karlsruhe | D257: publiziert | E257: 46240.668 | F257: org.apache.myfaces.view.facelets.component.UIRepeat@2db32431 | G257: HSP-8f8f7fcb-f9e8-37eb-9e28-dba210bf8b16 | H257: HSP-87d1c54b-efc9-3e78-968d-27672b7e2f19 | I257: https://resolver.staatsbibliothek-berlin.de/HSP0006DF6E00000000 | J257: 10112025 | K257: 13012025 | L257: EXTERN | M257: nein | N257: 865 | O257: -
A258: Cod. Donaueschingen D 5 | B258: Badische Landesbibliothek | C258: Karlsruhe | D258: publiziert | E258: 46240.668 | F258: org.apache.myfaces.view.facelets.component.UIRepeat@2db32431 | G258: HSP-99b3c51f-51cd-3a89-bfd3-af5f9dc5e2c9 | H258: HSP-870087bf-47b4-349d-839d-884beac033c8 | I258: https://resolver.staatsbibliothek-berlin.de/HSP0006DF7800000000 | J258: 18112025 | K258: 13012025 | L258: EXTERN | M258: nein | N258: 865 | O258: -
... A289: Cod. Donaueschingen 570b | B289: Badische Landesbibliothek | C289: Karlsruhe | D289: publiziert | E289: 46240.669 | F289: Sturm, Katrin | G289: HSP-4e12ceaa-df08-3d6b-9cb8-009306f6f1f3 | H289: HSP-b367b118-3f8c-32a9-b525-0c3216f2b8f2 | I289: https://resolver.staatsbibliothek-berlin.de/HSP0007122000000000 | J289: 30012026 | K289: 30012026 | L289: EXTERN | M289: nein | N289: 865 | O289: -
...
